<?xml version="1.0"?>

<robot name="small_bot" xmlns:xacro="http://ros.org/wiki/xacro">
  
  <link name="world"/>
  <joint name="fixed" type="fixed">
    <parent link="world"/>
    <child link="base_link"/>
  </joint>

  <link
    name="base_link">
    <inertial>
      <origin
        xyz="0.13684 0.11966 0.2484"
        rpy="0 0 0" />
      <mass
        value="3.5218" />
      <inertia
        ixx="0.028345"
        ixy="2.7288E-19"
        ixz="-1.7377E-19"
        iyy="0.055839"
        iyz="2.2243E-19"
        izz="0.028345" />
    </inertial>
    <visual>
      <origin
        xyz="0 0 0"
        rpy="0 0 0" />
      <geometry>
        <mesh
          filename="package://small_bot/meshes/base_link.STL" />
      </geometry>
      <material
        name="">
        <color
          rgba="0.49804 0.49804 0.49804 1" />
      </material>
    </visual>
    <collision>
      <origin
        xyz="0 0 0"
        rpy="0 0 0" />
      <geometry>
        <mesh
          filename="package://small_bot/meshes/base_link.STL" />
      </geometry>
    </collision>
  </link>
  <link
    name="Link1">
    <inertial>
      <origin
        xyz="0.0029801 0.3076 -1.501E-08"
        rpy="0 0 0" />
      <mass
        value="2.8813" />
      <inertia
        ixx="0.089865"
        ixy="-0.0020663"
        ixz="1.1533E-09"
        iyy="0.0027566"
        iyz="1.4071E-08"
        izz="0.090604" />
    </inertial>
    <visual>
      <origin
        xyz="0 0 0"
        rpy="0 0 0" />
      <geometry>
        <mesh
          filename="package://small_bot/meshes/Link1.STL" />
      </geometry>
      <material
        name="">
        <color
          rgba="0.49804 0.49804 0.49804 1" />
      </material>
    </visual>
    <collision>
      <origin
        xyz="0 0 0"
        rpy="0 0 0" />
      <geometry>
        <mesh
          filename="package://small_bot/meshes/Link1.STL" />
      </geometry>
    </collision>
  </link>
  <joint
    name="joint_1"
    type="revolute">
    <origin
      xyz="0.13684 -0.2484 0.1199"
      rpy="1.5708 0 1.2399" />
    <parent
      link="base_link" />
    <child
      link="Link1" />
    <axis
      xyz="0 1 0" />
    <limit
      lower="0"
      upper="3.5"
      effort="10"
      velocity="10" />
  </joint>
  <link
    name="Link2">
    <inertial>
      <origin
        xyz="0.12736 -0.19158 2.3346E-08"
        rpy="0 0 0" />
      <mass
        value="2.202" />
      <inertia
        ixx="0.042995"
        ixy="-0.00015156"
        ixz="1.7226E-09"
        iyy="0.0015715"
        iyz="-7.256E-09"
        izz="0.042979" />
    </inertial>
    <visual>
      <origin
        xyz="0 0 0"
        rpy="0 0 0" />
      <geometry>
        <mesh
          filename="package://small_bot/meshes/Link2.STL" />
      </geometry>
      <material
        name="">
        <color
          rgba="0.50196 0.50196 1 1" />
      </material>
    </visual>
    <collision>
      <origin
        xyz="0 0 0"
        rpy="0 0 0" />
      <geometry>
        <mesh
          filename="package://small_bot/meshes/Link2.STL" />
      </geometry>
    </collision>
  </link>
  <joint
    name="joint_2"
    type="revolute">
    <origin
      xyz="0 0.54824 0"
      rpy="-0.91174 0 0" />
    <parent
      link="Link1" />
    <child
      link="Link2" />
    <axis
      xyz="1 0 0" />
    <limit
      lower="0"
      upper="5"
      effort="5"
      velocity="10" />
  </joint>

  <transmission name="joint_1_transmission">
        <type>transmission_interface/SimpleTransmission</type>
        <joint name="joint_1">
            <hardwareInterface>hardware_interface/EffortJointInterface</hardwareInterface>
        </joint>
        <actuator name="joint_1_motor">
      <hardwareInterface>hardware_interface/EffortJointInterface</hardwareInterface>
            <mechanicalReduction>10</mechanicalReduction>
        </actuator>
        </transmission>

        <transmission name="joint_2_transmission">
        <type>transmission_interface/SimpleTransmission</type>
        <joint name="joint_2">
            <hardwareInterface>hardware_interface/EffortJointInterface</hardwareInterface>
        </joint>
        <actuator name="joint_2_motor">
      <hardwareInterface>hardware_interface/EffortJointInterface</hardwareInterface>
            <mechanicalReduction>10</mechanicalReduction>
        </actuator>
        </transmission>

  <gazebo>
  <plugin name="gazebo_ros_control" filename="libgazebo_ros_control.so">
    
    <robotNamespace>/small_bot</robotNamespace>
  </plugin>
</gazebo>

</robot>